Workbook

Sheet รายการสินค้า
A1: ลำดับ | B1: หมวดหมู่หลัก | C1: หมวดหมู่ย่อย | D1: รูปสินค้า | E1: รหัสสินค้า (SKU) | F1: รหัสบาร์โค้ด | G1: ชื่อสินค้า | H1: ขนาด/รุ่น | I1: หน่วย | J1: ราคาทุน | K1: ราคาขาย | L1: กลุ่มสินค้า | M1: ประเภทแถว | N1: รหัสสินค้าหลัก | O1: จำนวนหน่วยย่อยต่อ 1 หน่วยหลัก | P1: จำนวนคงเหลือ | Q1: ขั้นต่ำ | R1: สถานะ | S1: หมวดหมู่เดิมในไฟล์ต้นทาง (อ้างอิง)
A2: 1 | B2: ท่อพีวีซี | C2: ท่อพีวีซีสีเหลือง | D2: SKU05041.jpg | E2: SKU 05041 | F2: 2000000010168 | G2: ข้องอ 90 เหลือง | K2: 8 | L2: ข้องอ 90 เหลือง | M2: หลัก | P2: 0 | R2: ใช้ | S2: ท่อพีวีซี
A3: 2 | B3: ท่อพีวีซี | D3: 04901.jpg | E3: 04901 | F3: 2000000010175 | G3: ข้อต่อ ผม. PVC 1/2" SCG | K3: 12 | L3: ข้อต่อ ผม. PVC 1/2" SCG | M3: หลัก | P3: 0 | R3: ใช้ | S3: ท่อพีวีซี
A4: 3 | B4: ท่อพีวีซี | C4: ท่อพีวีซีสีเหลือง | D4: SKU05044.jpg | E4: SKU 05044 | F4: 2000000010199 | G4: คลิปก้ามปูเหลือง นาโน | K4: 4 | L4: คลิปก้ามปูเหลือง นาโน | M4: หลัก | P4: 0 | R4: ใช้ | S4: ท่อพีวีซี
A5: 4 | B5: ท่อพีวีซี | C5: ท่อพีวีซีสีฟ้า | D5: 1102913.jpg | E5: SKU1102820 | F5: 2000000010205 | G5: ตัดท่อ PVC ชั้น 13.5 สีฟ้า SCG | H5: 3/4" | K5: 35 | L5: ตัดท่อ PVC ชั้น 13.5 สีฟ้า SCG | M5: หลัก | P5: 0 | R5: ใช้ | S5: ท่อพีวีซี
A6: 5 | B6: ท่อพีวีซี | C6: ท่อพีวีซีสีฟ้า | D6: 1102913.jpg | E6: SKU1102821 | F6: 2000000010212 | G6: ตัดท่อ PVC ชั้น 13.5 สีฟ้า SCG | H6: 1" | K6: 50 | L6: ตัดท่อ PVC ชั้น 13.5 สีฟ้า SCG | M6: หลัก | P6: 0 | R6: ใช้ | S6: ท่อพีวีซี
A7: 6 | B7: ท่อพีวีซี | C7: ท่อพีวีซีสีฟ้า | D7: 1102913.jpg | E7: SKU1102822 | F7: 2000000010229 | G7: ตัดท่อ PVC ชั้น 13.5 สีฟ้า SCG | H7: 1-1/4" | K7: 65 | L7: ตัดท่อ PVC ชั้น 13.5 สีฟ้า SCG | M7: หลัก | P7: 0 | R7: ใช้ | S7: ท่อพีวีซี
A8: 7 | B8: ท่อพีวีซี | C8: ท่อพีวีซีสีฟ้า | D8: 1102913.jpg | E8: SKU1102823 | F8: 2000000010236 | G8: ตัดท่อ PVC ชั้น 13.5 สีฟ้า SCG | H8: 1-1/2" | K8: 90 | L8: ตัดท่อ PVC ชั้น 13.5 สีฟ้า SCG | M8: หลัก | P8: 0 | R8: ใช้ | S8: ท่อพีวีซี
A9: 8 | B9: ท่อพีวีซี | C9: ท่อพีวีซีสีฟ้า | D9: 1102913.jpg | E9: SKU1102824 | F9: 2000000010243 | G9: ตัดท่อ PVC ชั้น 13.5 สีฟ้า SCG | H9: 2" | K9: 130 | L9: ตัดท่อ PVC ชั้น 13.5 สีฟ้า SCG | M9: หลัก | P9: 0 | R9: ใช้ | S9: ท่อพีวีซี
A10: 9 | B10: ท่อพีวีซี | C10: ท่อพีวีซีสีฟ้า | D10: 1102913.jpg | E10: SKU1102827 | F10: 2000000010250 | G10: ตัดท่อ PVC ชั้น 13.5 สีฟ้า SCG | H10: 4" | K10: 450 | L10: ตัดท่อ PVC ชั้น 13.5 สีฟ้า SCG | M10: หลัก | P10: 0 | R10: ใช้ | S10: ท่อพีวีซี
A11: 10 | B11: ท่อพีวีซี | C11: ท่อพีวีซีสีฟ้า | D11: 1102913.jpg | E11: SKU1102826 | F11: 2000000010267 | G11: ตัดท่อ PVC ชั้น 13.5 สีฟ้า SCG | H11: 3" | K11: 300 | L11: ตัดท่อ PVC ชั้น 13.5 สีฟ้า SCG | M11: หลัก | P11: 0 | R11: ใช้ | S11: ท่อพีวีซี
A12: 11 | B12: ท่อพีวีซี | C12: ท่อพีวีซีสีฟ้า | D12: 1102913.jpg | E12: SKU1102825 | F12: 2000000010274 | G12: ตัดท่อ PVC ชั้น 13.5 สีฟ้า SCG | H12: 2-1/2" | K12: 220 | L12: ตัดท่อ PVC ชั้น 13.5 สีฟ้า SCG | M12: หลัก | P12: 0 | R12: ใช้ | S12: ท่อพีวีซี
A13: 12 | B13: ท่อพีวีซี | C13: ท่อพีวีซีสีฟ้า | D13: 1102913.jpg | E13: SKU1102819 | F13: 2000000010281 | G13: ตัดท่อ PVC ชั้น 13.5 สีฟ้า SCG | H13: 1/2" | K13: 30 | L13: ตัดท่อ PVC ชั้น 13.5 สีฟ้า SCG | M13: หลัก | P13: 0 | R13: ใช้ | S13: ท่อพีวีซี
A14: 13 | B14: ท่อพีวีซี | C14: ท่อพีวีซีสีฟ้า | D14: 02937.jpg | E14: SKU02843 | F14: 2000000010298 | G14: ตัดท่อ PVC ชั้น 13.5 สีฟ้า ตราเสือ | H14: 1/2" | K14: 28 | L14: ตัดท่อ PVC ชั้น 13.5 สีฟ้า ตราเสือ | M14: หลัก | P14: 0 | R14: ใช้ | S14: ท่อพีวีซี
A15: 14 | B15: ท่อพีวีซี | C15: ท่อพีวีซีสีฟ้า | D15: 02937.jpg | E15: SKU1102844 | F15: 2000000010304 | G15: ตัดท่อ PVC ชั้น 13.5 สีฟ้า ตราเสือ | H15: 3/4" | K15: 33 | L15: ตัดท่อ PVC ชั้น 13.5 สีฟ้า ตราเสือ | M15: หลัก | P15: 0 | R15: ใช้ | S15: ท่อพีวีซี
A16: 15 | B16: ท่อพีวีซี | C16: ท่อพีวีซีสีฟ้า | D16: 02937.jpg | E16: SKU02845 | F16: 2000000010311 | G16: ตัดท่อ PVC ชั้น 13.5 สีฟ้า ตราเสือ | H16: 1" | K16: 45 | L16: ตัดท่อ PVC ชั้น 13.5 สีฟ้า ตราเสือ | M16: หลัก | P16: 0 | R16: ใช้ | S16: ท่อพีวีซี
... A98: 97 | B98: ท่อพีวีซี | C98: ท่อพีวีซีสีฟ้า | D98: 02852.jpg | E98: SKU-03324 | F98: 2000000011196 | G98: ท่อ PVC ชั้น 8.5 สีฟ้า ตราเสือ | H98: 2-1/2" | K98: 349 | L98: ท่อ PVC ชั้น 8.5 สีฟ้า ตราเสือ | M98: หลัก | P98: 0 | R98: ใช้ | S98: ท่อพีวีซี
A99: 98 | B99: ท่อพีวีซี | D99: SKU05108.jpg | E99: SKU 05108 | F99: 2000000011219 | G99: ท่อพีวีซีสีดำ นาโน | K99: 52 | L99: ท่อพีวีซีสีดำ นาโน | M99: หลัก | P99: 0 | R99: ใช้ | S99: ท่อพีวีซี
A100: 99 | B100: ท่อพีวีซี | C100: ท่อพีวีซีสีเหลือง | D100: SKU05032.jpg | E100: SKU 05032 | F100: 2000000011226 | G100: ท่อพีวีซีสีเหลือง นาโน | K100: 45 | L100: ท่อพีวีซีสีเหลือง นาโน | M100: หลัก | P100: 0 | R100: ใช้ | S100: ท่อพีวีซี
A101: 100 | B101: ท่อพีวีซี | C101: ท่อพีวีซีสีขาว | D101: 02897.jpg | E101: SKU-03360 | F101: 2000000011233 | G101: ท่อลูกฟูก ขาว ตราช้าง | H101: 3/8" | K101: 690 | L101: ท่อลูกฟูก ขาว ตราช้าง | M101: หลัก | P101: 0 | R101: ใช้ | S101: ท่อพีวีซี
A102: 101 | B102: ท่อพีวีซี | C102: ท่อพีวีซีสีขาว | D102: 02897.jpg | E102: SKU-03361 | F102: 2000000011240 | G102: ท่อลูกฟูก ขาว ตราช้าง | H102: 1/2" | K102: 1100 | L102: ท่อลูกฟูก ขาว ตราช้าง | M102: หลัก | P102: 0 | R102: ใช้ | S102: ท่อพีวีซี
A103: 102 | B103: ท่อพีวีซี | C103: ท่อพีวีซีสีขาว | D103: 02897.jpg | E103: SKU-03362 | F103: 2000000011257 | G103: ท่อลูกฟูก ขาว ตราช้าง | H103: 3/4" | K103: 1190 | L103: ท่อลูกฟูก ขาว ตราช้าง | M103: หลัก | P103: 0 | R103: ใช้ | S103: ท่อพีวีซี
A104: 103 | B104: ท่อพีวีซี | C104: ท่อพีวีซีสีขาว | D104: 02897.jpg | E104: SKU-03363 | F104: 2000000011264 | G104: ท่อลูกฟูก ขาว ตราช้าง | H104: 1" | K104: 1190 | L104: ท่อลูกฟูก ขาว ตราช้าง | M104: หลัก | P104: 0 | R104: ใช้ | S104: ท่อพีวีซี
A105: 104 | B105: ท่อพีวีซี | C105: ท่อพีวีซีสีขาว | D105: 02905.jpg | E105: 9902905 | F105: 2000000011271 | G105: ท่อลูกฟูก นาโน สีขาว | H105: 16มิล | K105: 500 | L105: ท่อลูกฟูก นาโน สีขาว | M105: หลัก | P105: 0 | R105: ใช้ | S105: ท่อพีวีซี
A106: 105 | B106: ท่อพีวีซี | C106: ท่อพีวีซีสีขาว | D106: 02905.jpg | E106: 9902906 | F106: 2000000011288 | G106: ท่อลูกฟูก นาโน สีขาว | H106: 20มิล | K106: 750 | L106: ท่อลูกฟูก นาโน สีขาว | M106: หลัก | P106: 0 | R106: ใช้ | S106: ท่อพีวีซี
A107: 106 | B107: ท่อพีวีซี | C107: ท่อพีวีซีสีขาว | D107: 02905.jpg | E107: 9902907 | F107: 2000000011295 | G107: ท่อลูกฟูก นาโน สีขาว | H107: 25มิล | K107: 790 | L107: ท่อลูกฟูก นาโน สีขาว | M107: หลัก | P107: 0 | R107: ใช้ | S107: ท่อพีวีซี
A108: 107 | B108: ท่อพีวีซี | C108: ท่อพีวีซีสีขาว | D108: 02905.jpg | E108: 9902908 | F108: 2000000011301 | G108: ท่อลูกฟูก นาโน สีขาว | H108: 32มิล | K108: 850 | L108: ท่อลูกฟูก นาโน สีขาว | M108: หลัก | P108: 0 | R108: ใช้ | S108: ท่อพีวีซี
A109: 108 | B109: ท่อพีวีซี | C109: ท่อพีวีซีสีเหลือง | D109: 02901.jpg | E109: SKU-03365 | F109: 2000000011325 | G109: ท่อลูกฟูกสีเหลือง ตราช้าง | H109: 3/8" | K109: 690 | L109: ท่อลูกฟูกสีเหลือง ตราช้าง | M109: หลัก | P109: 0 | R109: ใช้ | S109: ท่อพีวีซี
A110: 109 | B110: ท่อพีวีซี | C110: ท่อพีวีซีสีเหลือง | D110: 02901.jpg | E110: SKU-03366 | F110: 2000000011332 | G110: ท่อลูกฟูกสีเหลือง ตราช้าง | H110: 1/2" | K110: 1100 | L110: ท่อลูกฟูกสีเหลือง ตราช้าง | M110: หลัก | P110: 0 | R110: ใช้ | S110: ท่อพีวีซี
A111: 110 | B111: ท่อพีวีซี | C111: ท่อพีวีซีสีเหลือง | D111: 02901.jpg | E111: SKU-03367 | F111: 2000000011349 | G111: ท่อลูกฟูกสีเหลือง ตราช้าง | H111: 3/4" | K111: 1190 | L111: ท่อลูกฟูกสีเหลือง ตราช้าง | M111: หลัก | P111: 0 | R111: ใช้ | S111: ท่อพีวีซี
A112: 111 | B112: ท่อพีวีซี | C112: ท่อพีวีซีสีเหลือง | D112: 02901.jpg | E112: SKU-03368 | F112: 2000000011356 | G112: ท่อลูกฟูกสีเหลือง ตราช้าง | H112: 1" | K112: 1190 | L112: ท่อลูกฟูกสีเหลือง ตราช้าง | M112: หลัก | P112: 0 | R112: ใช้ | S112: ท่อพีวีซี
... A116: 115 | B116: ท่อพีวีซี | C116: ท่อพีวีซีสีเหลือง | D116: 9902909.jpg | E116: 9902912 | F116: 2000000011394 | G116: ท่อลูกฟูกสีเหลืองนาโน | H116: 1" | K116: 890 | L116: ท่อลูกฟูกสีเหลืองนาโน | M116: หลัก | P116: 0 | R116: ใช้ | S116: ท่อพีวีซี
A117: 116 | B117: อุปกรณ์ท่อพีวีซี | D117: 05107.jpg | E117: 05107 | F117: 2000000011417 | G117: กรวยจราจร 50ซม. POLO | K117: 199 | L117: กรวยจราจร 50ซม. POLO | M117: หลัก | P117: 0 | R117: ใช้ | S117: อุปกรณ์ท่อพีวีซี
A118: 117 | B118: อุปกรณ์ท่อพีวีซี | C118: อุปกรณ์ท่อสีขาว | D118: 03385.jpg | E118: 03385 | F118: 2000000011424 | G118: กล่องพักสายกลมสีขาว ตราช้าง | K118: 25 | L118: กล่องพักสายกลมสีขาว ตราช้าง | M118: หลัก | P118: 0 | R118: ใช้ | S118: อุปกรณ์ท่อพีวีซี
A119: 118 | B119: อุปกรณ์ท่อพีวีซี | C119: อุปกรณ์ท่อสีเหลือง | D119: 03351.jpg | E119: 03351 | F119: 2000000011431 | G119: กล่องพักสายกลมสีเหลือง ตราช้าง | K119: 20 | L119: กล่องพักสายกลมสีเหลือง ตราช้าง | M119: หลัก | P119: 0 | R119: ใช้ | S119: อุปกรณ์ท่อพีวีซี
A120: 119 | B120: อุปกรณ์ท่อพีวีซี | D120: 02652.jpg | E120: 02652 | F120: 2000000011462 | G120: กาวทาท่อ EaleOne | K120: 25 | L120: กาวทาท่อ EaleOne | M120: หลัก | P120: 0 | R120: ใช้ | S120: อุปกรณ์ท่อพีวีซี
A121: 120 | B121: อุปกรณ์ท่อพีวีซี | D121: 03227.jpg | E121: 03227 | F121: 2000000011486 | G121: กิ๊ปจับท่อ PVC, แคลมป์จับท่อ PVC SCG | K121: 3 | L121: กิ๊ปจับท่อ PVC, แคลมป์จับท่อ PVC SCG | M121: หลัก | P121: 0 | R121: ใช้ | S121: อุปกรณ์ท่อพีวีซี
A122: 121 | B122: อุปกรณ์ท่อพีวีซี | D122: 03104.jpg | E122: 03104 | F122: 2000000011516 | G122: ข้องอ 45 PVC ตราช้าง | K122: 9 | L122: ข้องอ 45 PVC ตราช้าง | M122: หลัก | P122: 0 | R122: ใช้ | S122: อุปกรณ์ท่อพีวีซี
A123: 122 | B123: อุปกรณ์ท่อพีวีซี | D123: 03111.jpg | E123: 03111 | F123: 2000000011523 | G123: ข้องอ 45 บาง PVC ตราช้าง | K123: 12 | L123: ข้องอ 45 บาง PVC ตราช้าง | M123: หลัก | P123: 0 | R123: ใช้ | S123: อุปกรณ์ท่อพีวีซี
A124: 123 | B124: อุปกรณ์ท่อพีวีซี | D124: 03082.jpg | E124: 03082 | F124: 2000000011530 | G124: ข้องอ 90 PVC ตราช้าง | K124: 7 | L124: ข้องอ 90 PVC ตราช้าง | M124: หลัก | P124: 0 | R124: ใช้ | S124: อุปกรณ์ท่อพีวีซี
...

Sheet ต้องตรวจก่อนใช้จริง
A1: ประเด็น | B1: ชื่อสินค้า | C1: SKU ในไฟล์ | D1: รายละเอียด / สิ่งที่ต้องทำ
A2: แก้ให้แล้ว: SKU มีอักขระนำหน้า | B2: ด้ามจอบ | C2: 02531 | D2: เดิมคือ ": 02531" (มีโคลอนและเว้นวรรคนำหน้า) ตัดออกแล้วเพราะจะทำให้ค้น/สแกนรหัสไม่เจอ
A3: รหัสคล้ายกัน คนละสินค้า | B3: น้ำยา WD-40 | C3: SKU00681 | D3: รหัสตัวเลข 00681 ซ้ำกับสินค้าอื่นในไฟล์ (คำนำหน้า SKU ต่างกัน) ตรวจกับใบสินค้า/เว็บต้นทางว่ารหัสไหนถูก ไม่งั้นค้นด้วยเลขรหัสจะเจอสองสินค้า
A4: รหัสคล้ายกัน คนละสินค้า | B4: น้ำยา WD-40 300ml. | C4: 00681 | D4: รหัสตัวเลข 00681 ซ้ำกับสินค้าอื่นในไฟล์ (คำนำหน้า SKU ต่างกัน) ตรวจกับใบสินค้า/เว็บต้นทางว่ารหัสไหนถูก ไม่งั้นค้นด้วยเลขรหัสจะเจอสองสินค้า
A5: รหัสคล้ายกัน คนละสินค้า | B5: เทปพันสายไฟ ยี่ห้อ ยาซากิ | C5: SKU01432 | D5: รหัสตัวเลข 01432 ซ้ำกับสินค้าอื่นในไฟล์ (คำนำหน้า SKU ต่างกัน) ตรวจกับใบสินค้า/เว็บต้นทางว่ารหัสไหนถูก ไม่งั้นค้นด้วยเลขรหัสจะเจอสองสินค้า
A6: รหัสคล้ายกัน คนละสินค้า | B6: เทปพันสายไฟ ยาซากิ ดำ | C6: 01432 | D6: รหัสตัวเลข 01432 ซ้ำกับสินค้าอื่นในไฟล์ (คำนำหน้า SKU ต่างกัน) ตรวจกับใบสินค้า/เว็บต้นทางว่ารหัสไหนถูก ไม่งั้นค้นด้วยเลขรหัสจะเจอสองสินค้า
A7: รหัสคล้ายกัน คนละสินค้า | B7: มินิบอลวาล์ว SANWA (ผม.) | C7: 02629 | D7: รหัสตัวเลข 02629 ซ้ำกับสินค้าอื่นในไฟล์ (คำนำหน้า SKU ต่างกัน) ตรวจกับใบสินค้า/เว็บต้นทางว่ารหัสไหนถูก ไม่งั้นค้นด้วยเลขรหัสจะเจอสองสินค้า
A8: รหัสคล้ายกัน คนละสินค้า | B8: น้ำกลั่น | C8: SKU-02629 | D8: รหัสตัวเลข 02629 ซ้ำกับสินค้าอื่นในไฟล์ (คำนำหน้า SKU ต่างกัน) ตรวจกับใบสินค้า/เว็บต้นทางว่ารหัสไหนถูก ไม่งั้นค้นด้วยเลขรหัสจะเจอสองสินค้า
A9: รหัสคล้ายกัน คนละสินค้า | B9: มินิบอลวาล์ว SANWA ( มม. ) | C9: 02630 | D9: รหัสตัวเลข 02630 ซ้ำกับสินค้าอื่นในไฟล์ (คำนำหน้า SKU ต่างกัน) ตรวจกับใบสินค้า/เว็บต้นทางว่ารหัสไหนถูก ไม่งั้นค้นด้วยเลขรหัสจะเจอสองสินค้า
A10: รหัสคล้ายกัน คนละสินค้า | B10: น้ำกลั่น | C10: SKU-02630 | D10: รหัสตัวเลข 02630 ซ้ำกับสินค้าอื่นในไฟล์ (คำนำหน้า SKU ต่างกัน) ตรวจกับใบสินค้า/เว็บต้นทางว่ารหัสไหนถูก ไม่งั้นค้นด้วยเลขรหัสจะเจอสองสินค้า
A11: รหัสคล้ายกัน คนละสินค้า | B11: มินิบอลวาล์วสามทาง Sanwa | C11: 02632 | D11: รหัสตัวเลข 02632 ซ้ำกับสินค้าอื่นในไฟล์ (คำนำหน้า SKU ต่างกัน) ตรวจกับใบสินค้า/เว็บต้นทางว่ารหัสไหนถูก ไม่งั้นค้นด้วยเลขรหัสจะเจอสองสินค้า
A12: รหัสคล้ายกัน คนละสินค้า | B12: แชลค ขวด | C12: SKU-02632 | D12: รหัสตัวเลข 02632 ซ้ำกับสินค้าอื่นในไฟล์ (คำนำหน้า SKU ต่างกัน) ตรวจกับใบสินค้า/เว็บต้นทางว่ารหัสไหนถูก ไม่งั้นค้นด้วยเลขรหัสจะเจอสองสินค้า
... A52: ไม่มีรูปสินค้า | B52: เลื่อยฉลุฝ้า รุ่น 2 ใบ (ใบเลื่อยปลายแหลมและหยัก) | C52: 01070 | D52: ไม่มีไฟล์รูปในต้นทาง ถ่ายรูปเพิ่มภายหลังในหน้าสินค้า

Sheet ต้องตรวจสอบ (ไม่นำเข้า)
A1: ชื่อสินค้า | B1: SKU | C1: ขนาด | D1: หมวดหมู่ | E1: ราคาทุน | F1: ราคาขาย | G1: ยอดยกมา | H1: ไฟล์รูปภาพ | I1: บาร์โค้ด | J1: รหัสหมวดหมู่ | K1: กลุ่มสินค้า | L1: รหัสสินค้าหลัก | M1: หมายเหตุ (ต้องตรวจ) | N1: เหตุผลที่ไม่นำเข้า
A2: ข้อต่อ ผม. เหล็ก 1/2" | B2: 05069 | D2: ไม่ระบุหมวด | F2: 25 | G2: 0 | H2: 05069.jpg | I2: 2000000010014 | J2: C00 | K2: ข้อต่อ ผม. เหล็ก 1/2" | L2: 05069 | M2: ไม่พบหมวดหมู่ในไฟล์ต้นทาง ให้จัดหมวดเอง | N2: ไม่พบหมวดหมู่ในไฟล์ต้นทาง ให้จัดหมวดเอง
A3: ข้อต่อตรงเหล็ก | B3: SKU05057 | D3: ไม่ระบุหมวด | F3: 18 | G3: 0 | H3: SKU05057.jpg | I3: 2000000010021 | J3: C00 | K3: ข้อต่อตรงเหล็ก | L3: SKU05057 | M3: ไม่พบหมวดหมู่ในไฟล์ต้นทาง ให้จัดหมวดเอง | N3: ไม่พบหมวดหมู่ในไฟล์ต้นทาง ให้จัดหมวดเอง
A4: คาราบิเนอร์ สแตนเลส 304 | B4: SKU 05376 | D4: ไม่ระบุหมวด | F4: 25 | G4: 0 | H4: SKU05376.jpg | I4: 2000000010038 | J4: C00 | K4: คาราบิเนอร์ สแตนเลส 304 | L4: SKU 05376 | M4: ไม่พบหมวดหมู่ในไฟล์ต้นทาง ให้จัดหมวดเอง | N4: ไม่พบหมวดหมู่ในไฟล์ต้นทาง ให้จัดหมวดเอง
A5: ฉากยึด เครื่องกรองน้ำ สแตนเลส | B5: 05302 | D5: ไม่ระบุหมวด | F5: 39 | G5: 0 | H5: 05302.jpg | I5: 2000000010045 | J5: C00 | K5: ฉากยึด เครื่องกรองน้ำ สแตนเลส | L5: 05302 | M5: ไม่พบหมวดหมู่ในไฟล์ต้นทาง ให้จัดหมวดเอง | N5: ไม่พบหมวดหมู่ในไฟล์ต้นทาง ให้จัดหมวดเอง
A6: นิปเปิ้ลเหล็ก | B6: SKU05066 | D6: ไม่ระบุหมวด | F6: 22 | G6: 0 | H6: SKU05066.jpg | I6: 2000000010052 | J6: C00 | K6: นิปเปิ้ลเหล็ก | L6: SKU05066 | M6: ไม่พบหมวดหมู่ในไฟล์ต้นทาง ให้จัดหมวดเอง | N6: ไม่พบหมวดหมู่ในไฟล์ต้นทาง ให้จัดหมวดเอง
A7: ฟุตวาล์ว PVC สีดำ สวมสายดูด | B7: SKU05100 | D7: ไม่ระบุหมวด | F7: 179 | G7: 0 | H7: SKU05100.jpg | I7: 2000000010069 | J7: C00 | K7: ฟุตวาล์ว PVC สีดำ สวมสายดูด | L7: SKU05100 | M7: ไม่พบหมวดหมู่ในไฟล์ต้นทาง ให้จัดหมวดเอง | N7: ไม่พบหมวดหมู่ในไฟล์ต้นทาง ให้จัดหมวดเอง
A8: รอกเขียวเดี่ยว | B8: SKU05075 | D8: ไม่ระบุหมวด | F8: 379 | G8: 0 | H8: SKU05075.jpg | I8: 2000000010076 | J8: C00 | K8: รอกเขียวเดี่ยว | L8: SKU05075 | M8: ไม่พบหมวดหมู่ในไฟล์ต้นทาง ให้จัดหมวดเอง | N8: ไม่พบหมวดหมู่ในไฟล์ต้นทาง ให้จัดหมวดเอง
A9: รอกเชือก PVC Yokomo | B9: 05074 | D9: ไม่ระบุหมวด | F9: 100 | G9: 0 | H9: 05074.jpg | I9: 2000000010083 | J9: C00 | K9: รอกเชือก PVC Yokomo | L9: 05074 | M9: ไม่พบหมวดหมู่ในไฟล์ต้นทาง ให้จัดหมวดเอง | N9: ไม่พบหมวดหมู่ในไฟล์ต้นทาง ให้จัดหมวดเอง
A10: รางปลั๊กโตชิโน รุ่น 3600w TIS315-5ม. | B10: 04208 | D10: ไม่ระบุหมวด | F10: 780 | G10: 0 | H10: 04208.jpg | I10: 2000000010090 | J10: C00 | K10: รางปลั๊กโตชิโน รุ่น 3600w TIS315-5ม. | L10: 04208 | M10: ไม่พบหมวดหมู่ในไฟล์ต้นทาง ให้จัดหมวดเอง | N10: ไม่พบหมวดหมู่ในไฟล์ต้นทาง ให้จัดหมวดเอง
A11: สามทางลม 8มิล PE8 | B11: 05290 | D11: ไม่ระบุหมวด | F11: 19 | G11: 0 | H11: 05290.jpg | I11: 2000000010106 | J11: C00 | K11: สามทางลม 8มิล PE8 | L11: 05290 | M11: ไม่พบหมวดหมู่ในไฟล์ต้นทาง ให้จัดหมวดเอง | N11: ไม่พบหมวดหมู่ในไฟล์ต้นทาง ให้จัดหมวดเอง
A12: สามทางเหล็ก | B12: SKU05063 | D12: ไม่ระบุหมวด | F12: 27 | G12: 0 | H12: SKU05063.jpg | I12: 2000000010113 | J12: C00 | K12: สามทางเหล็ก | L12: SKU05063 | M12: ไม่พบหมวดหมู่ในไฟล์ต้นทาง ให้จัดหมวดเอง | N12: ไม่พบหมวดหมู่ในไฟล์ต้นทาง ให้จัดหมวดเอง
A13: หูสายยูชุบซิงค์ มุมฉาก ใหญ่หนา (แพค2ตัว) | B13: 05072 | D13: ไม่ระบุหมวด | F13: 70 | G13: 0 | H13: 05072.jpg | I13: 2000000010120 | J13: C00 | K13: หูสายยูชุบซิงค์ มุมฉาก ใหญ่หนา (แพค2ตัว) | L13: 05072 | M13: ไม่พบหมวดหมู่ในไฟล์ต้นทาง ให้จัดหมวดเอง | N13: ไม่พบหมวดหมู่ในไฟล์ต้นทาง ให้จัดหมวดเอง
... A28: กล่องพักสายสี่เหลี่ยมสีเหลือง ตราช้าง | B28: 03352 | D28: อุปกรณ์ท่อพีวีซี | F28: 20 | G28: 0 | H28: 03352.jpg | I28: 2000000011455 | J28: C03 | K28: กล่องพักสายสี่เหลี่ยมสีเหลือง ตราช้าง | L28: 03352 | M28: การ์ดนี้มีหลายแบบในเว็บต้นทาง (ช่วงราคา 20-30) แต่ไม่มีรายละเอียดแต่ละแบบในไฟล์ — ใส่ราคาต่ำสุด ให้ตรวจ/แยกแบบเอง | N28: การ์ดนี้มีหลายแบบในเว็บต้นทาง (ช่วงราคา 20-30) แต่ไม่มีรายละเอียดแต่ละแบบในไฟล์ — ใส่ราคาต่ำสุด ให้ตรวจ/แยกแบบเอง
A29: กาวทาท่อชนิดข้น SCG 250g | B29: 03546 | D29: อุปกรณ์ท่อพีวีซี | F29: 0 | G29: 0 | H29: 03546.jpg | I29: 2000000011479 | J29: C03 | K29: กาวทาท่อชนิดข้น SCG 250g | L29: 03546 | N29: ราคาขายเป็น 0 ต้องกรอกราคาที่ถูกต้อง
A30: กิ๊ปจับท่อ, แคล๊มป์จับท่อ ร้อยสายสีเหลือง ตราช้าง | B30: 03343 | D30: อุปกรณ์ท่อพีวีซี | F30: 3 | G30: 0 | H30: 03343.jpg | I30: 2000000011493 | J30: C03 | K30: กิ๊ปจับท่อ, แคล๊มป์จับท่อ ร้อยสายสีเหลือง ตราช้าง | L30: 03343 | M30: การ์ดนี้มีหลายแบบในเว็บต้นทาง (ช่วงราคา 3-5) แต่ไม่มีรายละเอียดแต่ละแบบในไฟล์ — ใส่ราคาต่ำสุด ให้ตรวจ/แยกแบบเอง | N30: การ์ดนี้มีหลายแบบในเว็บต้นทาง (ช่วงราคา 3-5) แต่ไม่มีรายละเอียดแต่ละแบบในไฟล์ — ใส่ราคาต่ำสุด ให้ตรวจ/แยกแบบเอง
A31: กิ๊ปจับท่อ, แคล๊มป์จับท่อ สังกะสี รุ่นบาง | B31: 03280 | D31: อุปกรณ์ท่อพีวีซี | F31: 3 | G31: 0 | H31: 03280.jpg | I31: 2000000011509 | J31: C03 | K31: กิ๊ปจับท่อ, แคล๊มป์จับท่อ สังกะสี รุ่นบาง | L31: 03280 | M31: การ์ดนี้มีหลายแบบในเว็บต้นทาง (ช่วงราคา 3-20) แต่ไม่มีรายละเอียดแต่ละแบบในไฟล์ — ใส่ราคาต่ำสุด ให้ตรวจ/แยกแบบเอง | N31: การ์ดนี้มีหลายแบบในเว็บต้นทาง (ช่วงราคา 3-20) แต่ไม่มีรายละเอียดแต่ละแบบในไฟล์ — ใส่ราคาต่ำสุด ให้ตรวจ/แยกแบบเอง
A32: ข้องอ 90 ร้อยสายสีขาว ตราช้าง | B32: 03368 | D32: อุปกรณ์ท่อพีวีซี | F32: 8 | G32: 0 | H32: 03368.jpg | I32: 2000000011561 | J32: C03 | K32: ข้องอ 90 ร้อยสายสีขาว ตราช้าง | L32: 03368 | M32: การ์ดนี้มีหลายแบบในเว็บต้นทาง (ช่วงราคา 8-12) แต่ไม่มีรายละเอียดแต่ละแบบในไฟล์ — ใส่ราคาต่ำสุด ให้ตรวจ/แยกแบบเอง | N32: การ์ดนี้มีหลายแบบในเว็บต้นทาง (ช่วงราคา 8-12) แต่ไม่มีรายละเอียดแต่ละแบบในไฟล์ — ใส่ราคาต่ำสุด ให้ตรวจ/แยกแบบเอง
A33: ข้องอ สวมอัด PE | B33: 04556 | D33: อุปกรณ์ท่อพีวีซี | F33: 70 | G33: 0 | H33: 04556.jpg | I33: 2000000011615 | J33: C03 | K33: ข้องอ สวมอัด PE | L33: 04556 | M33: การ์ดนี้มีหลายแบบในเว็บต้นทาง (ช่วงราคา 70-100) แต่ไม่มีรายละเอียดแต่ละแบบในไฟล์ — ใส่ราคาต่ำสุด ให้ตรวจ/แยกแบบเอง | N33: การ์ดนี้มีหลายแบบในเว็บต้นทาง (ช่วงราคา 70-100) แต่ไม่มีรายละเอียดแต่ละแบบในไฟล์ — ใส่ราคาต่ำสุด ให้ตรวจ/แยกแบบเอง
A34: ข้องอขาว นาโน | B34: 03400 | D34: อุปกรณ์ท่อพีวีซี | F34: 6 | G34: 0 | H34: 03400.jpg | I34: 2000000011639 | J34: C03 | K34: ข้องอขาว นาโน | L34: 03400 | M34: การ์ดนี้มีหลายแบบในเว็บต้นทาง (ช่วงราคา 6-12) แต่ไม่มีรายละเอียดแต่ละแบบในไฟล์ — ใส่ราคาต่ำสุด ให้ตรวจ/แยกแบบเอง | N34: การ์ดนี้มีหลายแบบในเว็บต้นทาง (ช่วงราคา 6-12) แต่ไม่มีรายละเอียดแต่ละแบบในไฟล์ — ใส่ราคาต่ำสุด ให้ตรวจ/แยกแบบเอง
A35: ข้อต่อตรง สวมอัด PE | B35: 04553 | D35: อุปกรณ์ท่อพีวีซี | F35: 60 | G35: 0 | H35: 04553.jpg | I35: 2000000011677 | J35: C03 | K35: ข้อต่อตรง สวมอัด PE | L35: 04553 | M35: การ์ดนี้มีหลายแบบในเว็บต้นทาง (ช่วงราคา 60-90) แต่ไม่มีรายละเอียดแต่ละแบบในไฟล์ — ใส่ราคาต่ำสุด ให้ตรวจ/แยกแบบเอง | N35: การ์ดนี้มีหลายแบบในเว็บต้นทาง (ช่วงราคา 60-90) แต่ไม่มีรายละเอียดแต่ละแบบในไฟล์ — ใส่ราคาต่ำสุด ให้ตรวจ/แยกแบบเอง
A36: ข้อต่อตรง เกลียวนอกทองเหลือง ตราช้าง SCG | B36: 03262 | D36: อุปกรณ์ท่อพีวีซี | F36: 55 | G36: 0 | H36: 03262.jpg | I36: 2000000011684 | J36: C03 | K36: ข้อต่อตรง เกลียวนอกทองเหลือง ตราช้าง SCG | L36: 03262 | M36: การ์ดนี้มีหลายแบบในเว็บต้นทาง (ช่วงราคา 55-120) แต่ไม่มีรายละเอียดแต่ละแบบในไฟล์ — ใส่ราคาต่ำสุด ให้ตรวจ/แยกแบบเอง | N36: การ์ดนี้มีหลายแบบในเว็บต้นทาง (ช่วงราคา 55-120) แต่ไม่มีรายละเอียดแต่ละแบบในไฟล์ — ใส่ราคาต่ำสุด ให้ตรวจ/แยกแบบเอง
A37: ข้อต่อตรงขาว นาโน | B37: 03392 | D37: อุปกรณ์ท่อพีวีซี | F37: 4 | G37: 0 | H37: 03392.jpg | I37: 2000000011691 | J37: C03 | K37: ข้อต่อตรงขาว นาโน | L37: 03392 | M37: การ์ดนี้มีหลายแบบในเว็บต้นทาง (ช่วงราคา 4-8) แต่ไม่มีรายละเอียดแต่ละแบบในไฟล์ — ใส่ราคาต่ำสุด ให้ตรวจ/แยกแบบเอง | N37: การ์ดนี้มีหลายแบบในเว็บต้นทาง (ช่วงราคา 4-8) แต่ไม่มีรายละเอียดแต่ละแบบในไฟล์ — ใส่ราคาต่ำสุด ให้ตรวจ/แยกแบบเอง
A38: ข้อต่อตรงร้อยสายสีขาว ตราช้าง | B38: 03354 | D38: อุปกรณ์ท่อพีวีซี | F38: 5 | G38: 0 | H38: 03354.jpg | I38: 2000000011714 | J38: C03 | K38: ข้อต่อตรงร้อยสายสีขาว ตราช้าง | L38: 03354 | M38: การ์ดนี้มีหลายแบบในเว็บต้นทาง (ช่วงราคา 5-10) แต่ไม่มีรายละเอียดแต่ละแบบในไฟล์ — ใส่ราคาต่ำสุด ให้ตรวจ/แยกแบบเอง | N38: การ์ดนี้มีหลายแบบในเว็บต้นทาง (ช่วงราคา 5-10) แต่ไม่มีรายละเอียดแต่ละแบบในไฟล์ — ใส่ราคาต่ำสุด ให้ตรวจ/แยกแบบเอง
A39: ข้อต่อตรงสายสีเหลือง ตราช้าง | B39: 03312 | D39: อุปกรณ์ท่อพีวีซี | F39: 6 | G39: 0 | H39: 03312.jpg | I39: 2000000011745 | J39: C03 | K39: ข้อต่อตรงสายสีเหลือง ตราช้าง | L39: 03312 | M39: การ์ดนี้มีหลายแบบในเว็บต้นทาง (ช่วงราคา 6-120) แต่ไม่มีรายละเอียดแต่ละแบบในไฟล์ — ใส่ราคาต่ำสุด ให้ตรวจ/แยกแบบเอง | N39: การ์ดนี้มีหลายแบบในเว็บต้นทาง (ช่วงราคา 6-120) แต่ไม่มีรายละเอียดแต่ละแบบในไฟล์ — ใส่ราคาต่ำสุด ให้ตรวจ/แยกแบบเอง
A40: ข้อต่อตรงเทา | B40: 03412 | D40: อุปกรณ์ท่อพีวีซี | F40: 5 | G40: 0 | H40: 03412.jpg | I40: 2000000011806 | J40: C03 | K40: ข้อต่อตรงเทา | L40: 03412 | M40: การ์ดนี้มีหลายแบบในเว็บต้นทาง (ช่วงราคา 5-8) แต่ไม่มีรายละเอียดแต่ละแบบในไฟล์ — ใส่ราคาต่ำสุด ให้ตรวจ/แยกแบบเอง | N40: การ์ดนี้มีหลายแบบในเว็บต้นทาง (ช่วงราคา 5-8) แต่ไม่มีรายละเอียดแต่ละแบบในไฟล์ — ใส่ราคาต่ำสุด ให้ตรวจ/แยกแบบเอง
A41: ข้อต่อท่อย่นเหลือง 18cm. | B41: 04483 | D41: อุปกรณ์ท่อพีวีซี | F41: 10 | G41: 0 | H41: 04483.jpg | I41: 2000000011813 | J41: C03 | K41: ข้อต่อท่อย่นเหลือง 18cm. | L41: 04483 | M41: การ์ดนี้มีหลายแบบในเว็บต้นทาง (ช่วงราคา 10-12) แต่ไม่มีรายละเอียดแต่ละแบบในไฟล์ — ใส่ราคาต่ำสุด ให้ตรวจ/แยกแบบเอง | N41: การ์ดนี้มีหลายแบบในเว็บต้นทาง (ช่วงราคา 10-12) แต่ไม่มีรายละเอียดแต่ละแบบในไฟล์ — ใส่ราคาต่ำสุด ให้ตรวจ/แยกแบบเอง
... A100: ขวานด้ามไม้ เหล็กหล่อ | B100: 02487 | D100: เครื่องมือเกษตรและสวน | F100: 220 | G100: 0 | H100: 02487.jpg | I100: 2000000013602 | J100: C06 | K100: ขวานด้ามไม้ เหล็กหล่อ | L100: 02487 | M100: การ์ดนี้มีหลายแบบในเว็บต้นทาง (ช่วงราคา 220-289) แต่ไม่มีรายละเอียดแต่ละแบบในไฟล์ — ใส่ราคาต่ำสุด ให้ตรวจ/แยกแบบเอง | N100: การ์ดนี้มีหลายแบบในเว็บต้นทาง (ช่วงราคา 220-289) แต่ไม่มีรายละเอียดแต่ละแบบในไฟล์ — ใส่ราคาต่ำสุด ให้ตรวจ/แยกแบบเอง
A101: ข้องอ PE | B101: 04544 | D101: เครื่องมือเกษตรและสวน | F101: 6 | G101: 0 | I101: 2000000013633 | J101: C06 | K101: ข้องอ PE | L101: 04544 | M101: การ์ดนี้มีหลายแบบในเว็บต้นทาง (ช่วงราคา 6-8) แต่ไม่มีรายละเอียดแต่ละแบบในไฟล์ — ใส่ราคาต่ำสุด ให้ตรวจ/แยกแบบเอง | ไม่มีรูปในไฟล์ต้นทาง | N101: การ์ดนี้มีหลายแบบในเว็บต้นทาง (ช่วงราคา 6-8) แต่ไม่มีรายละเอียดแต่ละแบบในไฟล์ — ใส่ราคาต่ำสุด ให้ตรวจ/แยกแบบเอง | ไม่มีรูปในไฟล์ต้นทาง
A102: ข้อต่อตรง PE | B102: 04541 | D102: เครื่องมือเกษตรและสวน | F102: 4 | G102: 0 | H102: 04541.jpg | I102: 2000000013657 | J102: C06 | K102: ข้อต่อตรง PE | L102: 04541 | M102: การ์ดนี้มีหลายแบบในเว็บต้นทาง (ช่วงราคา 4-6) แต่ไม่มีรายละเอียดแต่ละแบบในไฟล์ — ใส่ราคาต่ำสุด ให้ตรวจ/แยกแบบเอง | N102: การ์ดนี้มีหลายแบบในเว็บต้นทาง (ช่วงราคา 4-6) แต่ไม่มีรายละเอียดแต่ละแบบในไฟล์ — ใส่ราคาต่ำสุด ให้ตรวจ/แยกแบบเอง
A103: ข้อต่อสายไมโคร (แพค10ตัว) | B103: 04370 | D103: เครื่องมือเกษตรและสวน | F103: 15 | G103: 0 | H103: 04370.jpg | I103: 2000000013671 | J103: C06 | K103: ข้อต่อสายไมโคร (แพค10ตัว) | L103: 04370 | M103: การ์ดนี้มีหลายแบบในเว็บต้นทาง (ช่วงราคา 15-40) แต่ไม่มีรายละเอียดแต่ละแบบในไฟล์ — ใส่ราคาต่ำสุด ให้ตรวจ/แยกแบบเอง | N103: การ์ดนี้มีหลายแบบในเว็บต้นทาง (ช่วงราคา 15-40) แต่ไม่มีรายละเอียดแต่ละแบบในไฟล์ — ใส่ราคาต่ำสุด ให้ตรวจ/แยกแบบเอง
A104: จอบ ตราจรเข้ สามดาว | B104: 02522 | D104: เครื่องมือเกษตรและสวน | F104: 269 | G104: 0 | H104: 02522.jpg | I104: 2000000013718 | J104: C06 | K104: จอบ ตราจรเข้ สามดาว | L104: 02522 | M104: การ์ดนี้มีหลายแบบในเว็บต้นทาง (ช่วงราคา 269-299) แต่ไม่มีรายละเอียดแต่ละแบบในไฟล์ — ใส่ราคาต่ำสุด ให้ตรวจ/แยกแบบเอง | N104: การ์ดนี้มีหลายแบบในเว็บต้นทาง (ช่วงราคา 269-299) แต่ไม่มีรายละเอียดแต่ละแบบในไฟล์ — ใส่ราคาต่ำสุด ให้ตรวจ/แยกแบบเอง
A105: จอบตราปลา (เฉพาะหัว) | B105: 02524 | D105: เครื่องมือเกษตรและสวน | F105: 199 | G105: 0 | H105: 02524.jpg | I105: 2000000013725 | J105: C06 | K105: จอบตราปลา (เฉพาะหัว) | L105: 02524 | M105: การ์ดนี้มีหลายแบบในเว็บต้นทาง (ช่วงราคา 199-220) แต่ไม่มีรายละเอียดแต่ละแบบในไฟล์ — ใส่ราคาต่ำสุด ให้ตรวจ/แยกแบบเอง | N105: การ์ดนี้มีหลายแบบในเว็บต้นทาง (ช่วงราคา 199-220) แต่ไม่มีรายละเอียดแต่ละแบบในไฟล์ — ใส่ราคาต่ำสุด ให้ตรวจ/แยกแบบเอง
A106: ตัดมุ้งตาข่ายฟ้า (1ม.) | B106: 02534 | D106: เครื่องมือเกษตรและสวน | F106: 20 | G106: 0 | H106: 02534.jpg | I106: 2000000013824 | J106: C06 | K106: ตัดมุ้งตาข่ายฟ้า (1ม.) | L106: 02534 | M106: การ์ดนี้มีหลายแบบในเว็บต้นทาง (ช่วงราคา 20-30) แต่ไม่มีรายละเอียดแต่ละแบบในไฟล์ — ใส่ราคาต่ำสุด ให้ตรวจ/แยกแบบเอง | N106: การ์ดนี้มีหลายแบบในเว็บต้นทาง (ช่วงราคา 20-30) แต่ไม่มีรายละเอียดแต่ละแบบในไฟล์ — ใส่ราคาต่ำสุด ให้ตรวจ/แยกแบบเอง
A107: ถุงมือผ้า | B107: ขอบเหลือง | D107: เครื่องมือเกษตรและสวน | F107: 20 | G107: 0 | H107: cloth-glove-yellow.jpg | I107: 2000000013886 | J107: C06 | K107: ถุงมือผ้า | L107: ขอบเหลือง | M107: การ์ดนี้มีหลายแบบในเว็บต้นทาง (ช่วงราคา 20-25) แต่ไม่มีรายละเอียดแต่ละแบบในไฟล์ — ใส่ราคาต่ำสุด ให้ตรวจ/แยกแบบเอง | N107: การ์ดนี้มีหลายแบบในเว็บต้นทาง (ช่วงราคา 20-25) แต่ไม่มีรายละเอียดแต่ละแบบในไฟล์ — ใส่ราคาต่ำสุด ให้ตรวจ/แยกแบบเอง; SKU เป็นภาษาไทย/ไม่ใช่รหัสสินค้า ต้องใส่ SKU ที่ถูกต้อง
A108: ถุงมือหนังขุย | B108: 02508 | D108: เครื่องมือเกษตรและสวน | F108: 55 | G108: 0 | H108: 02508.jpg | I108: 2000000013978 | J108: C06 | K108: ถุงมือหนังขุย | L108: 02508 | M108: การ์ดนี้มีหลายแบบในเว็บต้นทาง (ช่วงราคา 55-65) แต่ไม่มีรายละเอียดแต่ละแบบในไฟล์ — ใส่ราคาต่ำสุด ให้ตรวจ/แยกแบบเอง | N108: การ์ดนี้มีหลายแบบในเว็บต้นทาง (ช่วงราคา 55-65) แต่ไม่มีรายละเอียดแต่ละแบบในไฟล์ — ใส่ราคาต่ำสุด ให้ตรวจ/แยกแบบเอง
A109: ถุงมือหนังแฟนซี | B109: 02506 | D109: เครื่องมือเกษตรและสวน | F109: 35 | G109: 0 | H109: 02506.jpg | I109: 2000000013985 | J109: C06 | K109: ถุงมือหนังแฟนซี | L109: 02506 | M109: การ์ดนี้มีหลายแบบในเว็บต้นทาง (ช่วงราคา 35-39) แต่ไม่มีรายละเอียดแต่ละแบบในไฟล์ — ใส่ราคาต่ำสุด ให้ตรวจ/แยกแบบเอง | N109: การ์ดนี้มีหลายแบบในเว็บต้นทาง (ช่วงราคา 35-39) แต่ไม่มีรายละเอียดแต่ละแบบในไฟล์ — ใส่ราคาต่ำสุด ให้ตรวจ/แยกแบบเอง
A110: สามทาง PE | B110: 04547 | D110: เครื่องมือเกษตรและสวน | F110: 7 | G110: 0 | I110: 2000000014050 | J110: C06 | K110: สามทาง PE | L110: 04547 | M110: การ์ดนี้มีหลายแบบในเว็บต้นทาง (ช่วงราคา 7-10) แต่ไม่มีรายละเอียดแต่ละแบบในไฟล์ — ใส่ราคาต่ำสุด ให้ตรวจ/แยกแบบเอง | ไม่มีรูปในไฟล์ต้นทาง | N110: การ์ดนี้มีหลายแบบในเว็บต้นทาง (ช่วงราคา 7-10) แต่ไม่มีรายละเอียดแต่ละแบบในไฟล์ — ใส่ราคาต่ำสุด ให้ตรวจ/แยกแบบเอง | ไม่มีรูปในไฟล์ต้นทาง
A111: สายยางน้ำ ใส แบ่งเมตร | B111: 02536 | D111: เครื่องมือเกษตรและสวน | F111: 6 | G111: 0 | H111: 02536.jpg | I111: 2000000014067 | J111: C06 | K111: สายยางน้ำ ใส แบ่งเมตร | L111: 02536 | M111: การ์ดนี้มีหลายแบบในเว็บต้นทาง (ช่วงราคา 6-79) แต่ไม่มีรายละเอียดแต่ละแบบในไฟล์ — ใส่ราคาต่ำสุด ให้ตรวจ/แยกแบบเอง | N111: การ์ดนี้มีหลายแบบในเว็บต้นทาง (ช่วงราคา 6-79) แต่ไม่มีรายละเอียดแต่ละแบบในไฟล์ — ใส่ราคาต่ำสุด ให้ตรวจ/แยกแบบเอง
A112: สายยางฟ้า เกรดA (นิ่ม) [1ม.] | B112: 02544 | D112: เครื่องมือเกษตรและสวน | F112: 25 | G112: 0 | H112: 02544.jpg | I112: 2000000014081 | J112: C06 | K112: สายยางฟ้า เกรดA (นิ่ม) [1ม.] | L112: 02544 | M112: การ์ดนี้มีหลายแบบในเว็บต้นทาง (ช่วงราคา 25-55) แต่ไม่มีรายละเอียดแต่ละแบบในไฟล์ — ใส่ราคาต่ำสุด ให้ตรวจ/แยกแบบเอง | N112: การ์ดนี้มีหลายแบบในเว็บต้นทาง (ช่วงราคา 25-55) แต่ไม่มีรายละเอียดแต่ละแบบในไฟล์ — ใส่ราคาต่ำสุด ให้ตรวจ/แยกแบบเอง
...

Sheet หมวดหมู่ (แม็ปกับระบบ)
A1: หมวดหมู่เดิมในไฟล์ต้นทาง | B1: หมวดหมู่หลักในระบบ | C1: หมวดหมู่ย่อยในระบบ | D1: จำนวนรายการ (ขนาด)
A2: กุญแจ ลูกบิด | B2: เครื่องมือช่าง ฮาร์ดแวร์ | C2: กุญแจ ลูกบิด | D2: =COUNTIF(รายการสินค้า!$S$2:$S$1711,A2) -> 21
A3: ก๊อกน้ำ | B3: อุปกรณ์ประปา ห้องน้ำ | C3: ก๊อกน้ำ | D3: =COUNTIF(รายการสินค้า!$S$2:$S$1711,A3) -> 35
A4: ทินเนอร์ น้ำมันสน | B4: สี อุปกรณ์ทาสี | C4: ทินเนอร์ น้ำมันสน | D4: =COUNTIF(รายการสินค้า!$S$2:$S$1711,A4) -> 32
A5: ท่อพีวีซี | B5: ท่อพีวีซี | C5: (ตามสีในชื่อสินค้า) | D5: =COUNTIF(รายการสินค้า!$S$2:$S$1711,A5) -> 115
A6: ฝักบัว สายฉีดชำระ | B6: อุปกรณ์ประปา ห้องน้ำ | C6: ฝักบัว สายฉีดชำระ | D6: =COUNTIF(รายการสินค้า!$S$2:$S$1711,A6) -> 88
A7: สายไฟ | B7: สายไฟ | D7: =COUNTIF(รายการสินค้า!$S$2:$S$1711,A7) -> 28
A8: หลอดไฟ | B8: อุปกรณ์ไฟฟ้า | C8: หลอดไฟ | D8: =COUNTIF(รายการสินค้า!$S$2:$S$1711,A8) -> 115
A9: อุปกรณ์ก่อสร้าง | B9: อุปกรณ์ก่อสร้าง | D9: =COUNTIF(รายการสินค้า!$S$2:$S$1711,A9) -> 60
A10: อุปกรณ์ทาสี | B10: สี อุปกรณ์ทาสี | C10: อุปกรณ์ทาสี | D10: =COUNTIF(รายการสินค้า!$S$2:$S$1711,A10) -> 90
A11: อุปกรณ์ทำความสะอาด | B11: อุปกรณ์ก่อสร้าง | C11: อุปกรณ์ทำความสะอาด | D11: =COUNTIF(รายการสินค้า!$S$2:$S$1711,A11) -> 36
A12: อุปกรณ์ท่อพีวีซี | B12: อุปกรณ์ท่อพีวีซี | C12: (ตามสีในชื่อสินค้า) | D12: =COUNTIF(รายการสินค้า!$S$2:$S$1711,A12) -> 60
A13: อุปกรณ์ประปา ห้องน้ำ | B13: อุปกรณ์ประปา ห้องน้ำ | D13: =COUNTIF(รายการสินค้า!$S$2:$S$1711,A13) -> 75
A14: อุปกรณ์ประปาอื่นๆ | B14: อุปกรณ์ประปา ห้องน้ำ | C14: อุปกรณ์ประปาอื่นๆ | D14: =COUNTIF(รายการสินค้า!$S$2:$S$1711,A14) -> 15
A15: อุปกรณ์ไฟฟ้าอื่นๆ | B15: อุปกรณ์ไฟฟ้า | C15: อุปกรณ์ไฟฟ้าอื่นๆ | D15: =COUNTIF(รายการสินค้า!$S$2:$S$1711,A15) -> 230
A16: เครื่องมือช่าง | B16: เครื่องมือช่าง ฮาร์ดแวร์ | C16: เครื่องมือช่าง | D16: =COUNTIF(รายการสินค้า!$S$2:$S$1711,A16) -> 143
A17: เครื่องมือช่าง ฮาร์ดแวร์ | B17: เครื่องมือช่าง ฮาร์ดแวร์ | D17: =COUNTIF(รายการสินค้า!$S$2:$S$1711,A17) -> 205
A18: เครื่องมือเกษตรและสวน | B18: เครื่องมือเกษตรและสวน | D18: =COUNTIF(รายการสินค้า!$S$2:$S$1711,A18) -> 68
A19: เครื่องมือเจาะ ดอกสว่าน | B19: เครื่องมือช่าง ฮาร์ดแวร์ | C19: เครื่องมือเจาะ ดอกสว่าน | D19: =COUNTIF(รายการสินค้า!$S$2:$S$1711,A19) -> 82
A20: เครื่องมือเชื่อม | B20: เครื่องมือช่าง ฮาร์ดแวร์ | C20: เครื่องมือเชื่อม | D20: =COUNTIF(รายการสินค้า!$S$2:$S$1711,A20) -> 19
A21: เครื่องเขียน | B21: เครื่องมือช่าง ฮาร์ดแวร์ | C21: เครื่องเขียน | D21: =COUNTIF(รายการสินค้า!$S$2:$S$1711,A21) -> 17
A22: เทปกาว กาว ซิลิโคน | B22: เครื่องมือช่าง ฮาร์ดแวร์ | C22: เทปกาว กาว ซิลิโคน | D22: =COUNTIF(รายการสินค้า!$S$2:$S$1711,A22) -> 97
A23: ใบตัด ใบเจียร์ กระดาษทราย | B23: เครื่องมือช่าง ฮาร์ดแวร์ | C23: ใบตัด ใบเจียร์ กระดาษทราย | D23: =COUNTIF(รายการสินค้า!$S$2:$S$1711,A23) -> 79
A24: รวม | D24: =SUM(D2:D23) -> 1710

Sheet วิธีใช้
A1: วิธีใช้และสถานะไฟล์ | B1: ค่า
A2: ไฟล์นี้ใช้นำเข้าในแอปได้ทันที: หน้าสินค้า → นำเข้าจากไฟล์ (ชีตแรก "รายการสินค้า" เท่านั้นที่ถูกอ่าน)
A3: คอลัมน์ตรงกับรูปแบบไฟล์ส่งออกของแอป หมวดหมู่ใช้ชื่อตามผังหมวดหมู่ของแอป จึงไม่สร้างหมวดซ้ำ
A4: ช่องสีเหลือง (ราคาทุน) ต้องกรอกจากใบซื้อจริง: ถ้าว่าง ระบบบันทึกทุน 0 และกำไรจะสูงเกินจริง
A5: จำนวนแถวสินค้าในชีตรายการ | B5: =COUNTA(รายการสินค้า!E2:E1711) -> 1710
A6: แถวที่ราคาทุนยังว่าง | B6: =COUNTBLANK(รายการสินค้า!J2:J1711) -> 1710
A7: แถวที่ราคาขายยังว่างหรือเป็น 0 (ต้องเป็น 0) | B7: =COUNTBLANK(รายการสินค้า!K2:K1711)+COUNTIF(รายการสินค้า!K2:K1711,0) -> 0
A8: ยอดยกมาทั้งหมดเป็น 0: ถ้ามีสต็อกจริง ให้กรอกคอลัมน์ "จำนวนคงเหลือ" ก่อนนำเข้า (หรือนับสต็อกแล้วปรับหลังนำเข้า)
A9: รูปภาพ: ไฟล์นี้ใส่เฉพาะ "ชื่อไฟล์รูป" ไม่ได้ฝังรูป — ให้นำเข้ารูปด้วยปุ่มจับคู่รูปภาพ โดยเลือก image_mapping.json และไฟล์รูปในโฟลเดอร์ images/ พร้อมกัน
A10: ชีต "ต้องตรวจสอบ (ไม่นำเข้า)" 266 แถว ยังไม่ผ่านการตรวจ (หลายแบบขนาด/ไม่มีราคา/หมวดเดา) จึงไม่รวมในรายการนำเข้า ต้องแยกแบบและกรอกราคาเองก่อน
A11: ชีต "ต้องตรวจก่อนใช้จริง" สรุปรหัสที่แก้แล้วและรายการที่ควรยืนยัน (รหัสคล้ายกัน ราคาผิดปกติ ไม่มีรูป)
